<?xml version="1.0" ?>
<robot name="panda">
  <!--    Root world link-->
  <link name="world"/>
  <joint name="world_joint" type="fixed">
    <parent link="world"/>
    <child link="omni_base_root_link"/>
  </joint>
  <link name="omni_base_root_link"/>
  <link name="x_slider">
    <inertial>
      <origin rpy="0 0 0" xyz="0.0 0.0 0.0"/>
      <mass value="0.01"/>
      <inertia ixx="0.01" ixy="0.0" ixz="0.0" iyy="0.01" iyz="0.0" izz="0.01"/>
    </inertial>
  </link>
  <link name="y_slider">
    <inertial>
      <origin rpy="0 0 0" xyz="0.0 0.0 0.0"/>
      <mass value="0.01"/>
      <inertia ixx="0.01" ixy="0.0" ixz="0.0" iyy="0.01" iyz="0.0" izz="0.01"/>
    </inertial>
  </link>
  <link name="pivot">
    <inertial>
      <origin rpy="0 0 0" xyz="0.0 0.0 0.0"/>
      <mass value="0.01"/>
      <inertia ixx="0.01" ixy="0.0" ixz="0.0" iyy="0.01" iyz="0.0" izz="0.01"/>
    </inertial>
  </link>
  <joint name="x_base_joint" type="prismatic">
    <parent link="omni_base_root_link"/>
    <child link="x_slider"/>
    <origin rpy="0 0 0" xyz="0.0 0.0 0.0"/>
    <axis xyz="1 0 0"/>
    <limit effort="1000.0" lower="-10" upper="10" velocity="1.0"/>
    <dynamics damping="0.0" friction="10"/>
  </joint>
  <transmission name="transmision_x_base_joint">
    <type>transmission_interface/SimpleTransmission</type>
    <joint name="x_base_joint">
      <hardwareInterface>hardware_interface/EffortJointInterface</hardwareInterface>
    </joint>
    <actuator name="x_base_joint_motor">
      <mechanicalReduction>1</mechanicalReduction>
    </actuator>
  </transmission>
  <joint name="y_base_joint" type="prismatic">
    <parent link="x_slider"/>
    <child link="y_slider"/>
    <origin rpy="0 0 0" xyz="0.0 0.0 0.0"/>
    <axis xyz="0 1 0"/>
    <limit effort="1000.0" lower="-10" upper="10" velocity="1.0"/>
    <dynamics damping="0.0" friction="10"/>
  </joint>
  <transmission name="transmision_y_base_joint">
    <type>transmission_interface/SimpleTransmission</type>
    <joint name="y_base_joint">
      <hardwareInterface>hardware_interface/EffortJointInterface</hardwareInterface>
    </joint>
    <actuator name="y_base_joint_motor">
      <mechanicalReduction>1</mechanicalReduction>
    </actuator>
  </transmission>
  <joint name="pivot_joint" type="revolute">
    <parent link="y_slider"/>
    <child link="pivot"/>
    <origin rpy="0 0 0" xyz="0.0 0.0 0.0"/>
    <axis xyz="0 0 1"/>
    <limit effort="1000.0" lower="-10.0" upper="10.0" velocity="1.0"/>
    <dynamics damping="0.0" friction="10"/>
  </joint>
  <transmission name="transmision_pivot_joint">
    <type>transmission_interface/SimpleTransmission</type>
    <joint name="pivot_joint">
      <hardwareInterface>hardware_interface/EffortJointInterface</hardwareInterface>
    </joint>
    <actuator name="pivot_joint_motor">
      <mechanicalReduction>1</mechanicalReduction>
    </actuator>
  </transmission>
  <joint name="omni_base_flange" type="fixed">
    <parent link="pivot"/>
    <child link="base_link"/>
  </joint>
  <material name="dark_grey">
    <color rgba="0.2 0.2 0.2 1.0"/>
  </material>
  <material name="light_grey">
    <color rgba="0.4 0.4 0.4 1.0"/>
  </material>
  <material name="red">
    <color rgba="0.8 0.0 0.0 1.0"/>
  </material>
  <material name="white">
    <color rgba="0.9 0.9 0.9 1.0"/>
  </material>
  <material name="yellow">
    <color rgba="0.8 0.8 0.0 1.0"/>
  </material>
  <material name="black">
    <color rgba="0.15 0.15 0.15 1.0"/>
  </material>
  <!--    Only base link contains the collision bodies-->
  <link name="base_link">
    <inertial>
      <origin rpy="0 0 0" xyz="0 0 0.25"/>
      <mass value="1.0"/>
      <inertia ixx="0.048966669" ixy="0" ixz="0" iyy="0.046466667" iyz="0" izz="0.0041666669"/>
    </inertial>
  </link>
  <joint name="base_link_joint" type="fixed">
    <origin rpy="0 0 0" xyz="0 0 0"/>
    <parent link="base_link"/>
    <child link="chassis_link"/>
  </joint>
  <link name="chassis_link">
    <visual>
      <origin rpy="0 0 0" xyz="0 0 0"/>
      <geometry>
        <mesh filename="mppi_manipulation/data/meshes/ridgeback/meshes/body.stl"/>
      </geometry>
      <material name="black"/>
    </visual>
    <inertial>
      <origin rpy="1.5707963267948966 0 1.5707963267948966" xyz="0.012 0.002 0.067"/>
      <mass value="165.304"/>
      <inertia ixx="4.4744" ixy="0.03098" ixz="0.003647" iyy="7.1624" iyz="0.1228" izz="4.6155"/>
    </inertial>
  </link>
  <joint name="right_side_cover_link_joint" type="fixed">
    <origin rpy="0 0 0" xyz="0 0 0"/>
    <parent link="chassis_link"/>
    <child link="right_side_cover_link"/>
  </joint>
  <joint name="left_side_cover_link_joint" type="fixed">
    <origin rpy="0 0 0" xyz="0 0 0"/>
    <parent link="chassis_link"/>
    <child link="left_side_cover_link"/>
  </joint>
  <link name="left_side_cover_link">
    <visual>
      <origin rpy="0 0 3.141592653589793" xyz="0 0 0"/>
      <geometry>
        <mesh filename="mppi_manipulation/data/meshes/ridgeback/meshes/side-cover.stl"/>
      </geometry>
      <material name="yellow"/>
    </visual>
  </link>
  <link name="right_side_cover_link">
    <visual>
      <origin rpy="0 0 0" xyz="0 0 0"/>
      <geometry>
        <mesh filename="mppi_manipulation/data/meshes/ridgeback/meshes/side-cover.stl"/>
      </geometry>
      <material name="yellow"/>
    </visual>
  </link>
  <joint name="front_cover_link_joint" type="fixed">
    <origin rpy="0 0 0" xyz="0 0 0"/>
    <parent link="chassis_link"/>
    <child link="front_cover_link"/>
  </joint>
  <link name="front_cover_link">
    <visual>
      <origin rpy="0 0 0" xyz="0 0 0"/>
      <geometry>
        <mesh filename="mppi_manipulation/data/meshes/ridgeback/meshes/end-cover.stl"/>
      </geometry>
      <material name="black"/>
    </visual>
  </link>
  <joint name="rear_cover_link_joint" type="fixed">
    <origin rpy="0 0 0" xyz="0 0 0"/>
    <parent link="chassis_link"/>
    <child link="rear_cover_link"/>
  </joint>
  <link name="rear_cover_link">
    <visual>
      <origin rpy="0 0 3.141592653589793" xyz="0 0 0"/>
      <geometry>
        <mesh filename="mppi_manipulation/data/meshes/ridgeback/meshes/end-cover.stl"/>
      </geometry>
      <material name="black"/>
    </visual>
  </link>
  <joint name="front_lights_link_joint" type="fixed">
    <origin rpy="0 0 0" xyz="0 0 0"/>
    <parent link="chassis_link"/>
    <child link="front_lights_link"/>
  </joint>
  <joint name="rear_lights_link_joint" type="fixed">
    <origin rpy="0 0 0" xyz="0 0 0"/>
    <parent link="chassis_link"/>
    <child link="rear_lights_link"/>
  </joint>
  <link name="front_lights_link">
    <visual>
      <origin rpy="0 0 0" xyz="0 0 0"/>
      <geometry>
        <mesh filename="mppi_manipulation/data/meshes/ridgeback/meshes/lights.stl"/>
      </geometry>
      <material name="white"/>
    </visual>
  </link>
  <link name="rear_lights_link">
    <visual>
      <origin rpy="0 0 3.141592653589793" xyz="0 0 0"/>
      <geometry>
        <mesh filename="mppi_manipulation/data/meshes/ridgeback/meshes/lights.stl"/>
      </geometry>
      <material name="red"/>
    </visual>
  </link>
  <joint name="top_link_joint" type="fixed">
    <origin rpy="0 0 0" xyz="0 0 0"/>
    <parent link="chassis_link"/>
    <child link="top_link"/>
  </joint>
  <link name="top_link">
    <visual>
      <origin rpy="0 0 0" xyz="0 0 0"/>
      <geometry>
        <mesh filename="mppi_manipulation/data/meshes/ridgeback/meshes/top.stl"/>
      </geometry>
      <material name="black"/>
    </visual>
  </link>
  <joint name="axle_joint" type="fixed">
    <origin rpy="0 0 0" xyz="0 0 0.05"/>
    <parent link="chassis_link"/>
    <child link="axle_link"/>
  </joint>
  <link name="axle_link">
    <visual>
      <origin rpy="0 1.5707963267948966 0" xyz="0 0 0"/>
      <geometry>
        <mesh filename="mppi_manipulation/data/meshes/ridgeback/meshes/axle.stl"/>
      </geometry>
      <material name="black"/>
    </visual>
  </link>
  <link name="imu_link">
    <inertial>
      <mass value="0.001"/>
      <origin rpy="0 0 0" xyz="0 0 0"/>
      <inertia ixx="1e-09" ixy="0.0" ixz="0.0" iyy="1e-09" iyz="0.0" izz="1e-09"/>
    </inertial>
  </link>
  <joint name="imu_joint" type="fixed">
    <parent link="chassis_link"/>
    <child link="imu_link"/>
    <origin rpy="0 0 0" xyz="0.2085 -0.2902 0.1681"/>
  </joint>
  <link name="mid_mount"/>
  <joint name="mid_mount_joint" type="fixed">
    <parent link="base_link"/>
    <child link="mid_mount"/>
    <origin rpy="0 0 0" xyz="0 0 0.28"/>
  </joint>
  <!-- Sensor mount -->
  <link name="ridgeback_sensor_mount_link">
    <!--
    <visual>
        <geometry>
            <mesh filename="mppi_manipulation/data/meshes/ridgeback_sensor_mount.dae"/>
        </geometry>
    </visual> -->
  </link>
  <joint name="ridgeback_sensor_mount_joint" type="fixed">
    <origin rpy="0 0 1.571" xyz="0 0 0"/>
    <parent link="mid_mount"/>
    <child link="ridgeback_sensor_mount_link"/>
  </joint>
  <link name="reference_link"/>
  <joint name="reference_link_joint" type="fixed">
    <origin rpy="0 0 0" xyz="-0.343 0 0.77"/>
    <parent link="mid_mount"/>
    <child link="reference_link"/>
  </joint>
  <!--Mount panda on ridgeback-->
  <joint name="arm_mount_joint" type="fixed">
    <parent link="mid_mount"/>
    <child link="franka_mount_link"/>
    <!--        <origin xyz="$(optenv RIDGEBACK_FRANKA_XYZ 0.21 0.0 0.2)" rpy="$(optenv RIDGEBACK_FRANKA_RPY 0 0 0)"/>-->
    <origin rpy="0 0 0" xyz="0.295 0.005 0.445"/>
  </joint>
  <link name="franka_mount_link"/>
  <joint name="panda_joint_franka_mount_link" type="fixed">
    <parent link="franka_mount_link"/>
    <child link="panda_link0"/>
    <origin rpy="0 0 0" xyz="0 0 0"/>
  </joint>
  <!--
      <gazebo>
        <plugin filename="libgazebo_ros_control.so" name="gazebo_ros_control">
          <robotNamespace>/</robotNamespace>
          <robotParam>/</robotParam>
        </plugin>
      </gazebo>
      <gazebo reference="panda_link0"/>
      <gazebo reference="panda_link1"/>
      <gazebo reference="panda_link2"/>
      <gazebo reference="panda_link3"/>
      <gazebo reference="panda_link4"/>
      <gazebo reference="panda_link5"/>
      <gazebo reference="panda_link6"/>
      <gazebo reference="panda_link7"/>
      <gazebo reference="panda_link8"/>
  -->
  <transmission name="panda_joint1_trans">
    <type>transmission_interface/SimpleTransmission</type>
    <joint name="panda_joint1">
      <hardwareInterface>hardware_interface/EffortJointInterface</hardwareInterface>
    </joint>
    <actuator name="panda_joint1_motor">
      <mechanicalReduction>1</mechanicalReduction>
    </actuator>
  </transmission>
  <transmission name="panda_joint2_trans">
    <type>transmission_interface/SimpleTransmission</type>
    <joint name="panda_joint2">
      <hardwareInterface>hardware_interface/EffortJointInterface</hardwareInterface>
    </joint>
    <actuator name="panda_joint2_motor">
      <mechanicalReduction>1</mechanicalReduction>
    </actuator>
  </transmission>
  <transmission name="panda_joint3_trans">
    <type>transmission_interface/SimpleTransmission</type>
    <joint name="panda_joint3">
      <hardwareInterface>hardware_interface/EffortJointInterface</hardwareInterface>
    </joint>
    <actuator name="panda_joint3_motor">
      <mechanicalReduction>1</mechanicalReduction>
    </actuator>
  </transmission>
  <transmission name="panda_joint4_trans">
    <type>transmission_interface/SimpleTransmission</type>
    <joint name="panda_joint4">
      <hardwareInterface>hardware_interface/EffortJointInterface</hardwareInterface>
    </joint>
    <actuator name="panda_joint4_motor">
      <mechanicalReduction>1</mechanicalReduction>
    </actuator>
  </transmission>
  <transmission name="panda_joint5_trans">
    <type>transmission_interface/SimpleTransmission</type>
    <joint name="panda_joint5">
      <hardwareInterface>hardware_interface/EffortJointInterface</hardwareInterface>
    </joint>
    <actuator name="panda_joint5_motor">
      <mechanicalReduction>1</mechanicalReduction>
    </actuator>
  </transmission>
  <transmission name="panda_joint6_trans">
    <type>transmission_interface/SimpleTransmission</type>
    <joint name="panda_joint6">
      <hardwareInterface>hardware_interface/EffortJointInterface</hardwareInterface>
    </joint>
    <actuator name="panda_joint6_motor">
      <mechanicalReduction>1</mechanicalReduction>
    </actuator>
  </transmission>
  <transmission name="panda_joint7_trans">
    <type>transmission_interface/SimpleTransmission</type>
    <joint name="panda_joint7">
      <hardwareInterface>hardware_interface/EffortJointInterface</hardwareInterface>
    </joint>
    <actuator name="panda_joint7_motor">
      <mechanicalReduction>1</mechanicalReduction>
    </actuator>
  </transmission>



  <!-- arm links start here -->
  <link name="panda_link0">
    <inertial>
      <mass value="0.01"/>
      <origin rpy="0 0 0" xyz="0 0 0"/>
      <inertia ixx="0.001" ixy="0" ixz="0" iyy="0.001" iyz="0" izz="0.001"/>
    </inertial>
  </link>
  <link name="panda_link1">
   <inertial>
      <mass value="0.01"/>
      <origin rpy="0 0 0" xyz="0 0 0"/>
      <inertia ixx="0.001" ixy="0" ixz="0" iyy="0.001" iyz="0" izz="0.001"/>
    </inertial>
  </link>
  <!-- panda_joint1 is a dummy joint (i.e. panda_link1 is not connected to anything downstream) -->
  <joint name="panda_joint1" type="prismatic">
    <safety_controller k_position="100.0" k_velocity="40.0" soft_lower_limit="-10" soft_upper_limit="10"/>
    <origin rpy="0 0 0" xyz="0 0 0"/>
    <parent link="panda_link0"/>
    <child link="panda_link1"/>
    <axis xyz="1 0 0"/>
    <limit effort="1000" lower="-20" upper="20" velocity="10"/>
    <dynamics damping="0.0" friction="0.0"/>
  </joint>
  <link name="panda_link2">
    <inertial>
      <mass value="0.01"/>
      <origin rpy="0 0 0" xyz="0 0 0"/>
      <inertia ixx="0.001" ixy="0" ixz="0" iyy="0.001" iyz="0" izz="0.001"/>
    </inertial>
  </link>
  <joint name="panda_joint2" type="prismatic">
    <safety_controller k_position="100.0" k_velocity="40.0" soft_lower_limit="-10" soft_upper_limit="10"/>
    <origin rpy="0 0 0" xyz="0 0 0"/>
    <parent link="panda_link0"/>
    <child link="panda_link2"/>
    <axis xyz="1 0 0"/>
    <limit effort="1000" lower="-20" upper="20" velocity="10"/>
    <dynamics damping="0.0" friction="0.0"/>
  </joint>
  <link name="panda_link3">
    <inertial>
      <mass value="0.01"/>
      <origin rpy="0 0 0" xyz="0 0 0"/>
      <inertia ixx="0.001" ixy="0" ixz="0" iyy="0.001" iyz="0" izz="0.001"/>
    </inertial>
  </link>
  <joint name="panda_joint3" type="prismatic">
    <safety_controller k_position="100.0" k_velocity="40.0" soft_lower_limit="-10" soft_upper_limit="10"/>
    <origin rpy="0 0 0" xyz="0 0 0"/>
    <parent link="panda_link2"/>
    <child link="panda_link3"/>
    <axis xyz="0 1 0"/>
    <limit effort="1000" lower="-20" upper="20" velocity="10"/>
    <dynamics damping="0.0" friction="0.0"/>
  </joint>
  <link name="panda_link4">
    <inertial>
      <mass value="0.01"/>
      <origin rpy="0 0 0" xyz="0 0 0"/>
      <inertia ixx="0.001" ixy="0" ixz="0" iyy="0.001" iyz="0" izz="0.001"/>
    </inertial>
  </link>
  <joint name="panda_joint4" type="prismatic">
    <safety_controller k_position="100.0" k_velocity="40.0" soft_lower_limit="-10" soft_upper_limit="10"/>
    <origin rpy="0 0 0" xyz="0 0 0"/>
    <parent link="panda_link3"/>
    <child link="panda_link4"/>
    <axis xyz="0 0 1"/>
    <limit effort="87" lower="-20" upper="20" velocity="10"/>
    <dynamics damping="0.0" friction="0.0"/>
  </joint>
  <link name="panda_link5">
    <inertial>
      <mass value="0.01"/>
      <origin rpy="0 0 0" xyz="0 0 0"/>
      <inertia ixx="0.001" ixy="0" ixz="0" iyy="0.001" iyz="0" izz="0.001"/>
    </inertial>
  </link>
  <joint name="panda_joint5" type="revolute">
    <safety_controller k_position="100.0" k_velocity="40.0" soft_lower_limit="-30" soft_upper_limit="30"/>
    <origin rpy="0 0 0" xyz="0 0 0"/>
    <parent link="panda_link4"/>
    <child link="panda_link5"/>
    <axis xyz="1 0 0"/>
    <limit effort="87" lower="-60" upper="60" velocity="30"/>
    <dynamics damping="0.0" friction="0.0"/>
  </joint>
  <link name="panda_link6">
    <inertial>
      <mass value="0.01"/>
      <origin rpy="0 0 0" xyz="0 0 0"/>
      <inertia ixx="0.001" ixy="0" ixz="0" iyy="0.001" iyz="0" izz="0.001"/>
    </inertial>
  </link>
  <joint name="panda_joint6" type="revolute">
    <safety_controller k_position="100.0" k_velocity="40.0" soft_lower_limit="-30" soft_upper_limit="30"/>
    <origin rpy="0 0 0" xyz="0 0 0"/>
    <parent link="panda_link5"/>
    <child link="panda_link6"/>
    <axis xyz="0 1 0"/>
    <limit effort="87" lower="-60" upper="60" velocity="30"/>
    <dynamics damping="0.0" friction="0.0"/>
  </joint>
  <link name="panda_link7">
    <inertial>
      <mass value="0.01"/>
      <origin rpy="0 0 0" xyz="0 0 0"/>
      <inertia ixx="0.001" ixy="0" ixz="0" iyy="0.001" iyz="0" izz="0.001"/>
    </inertial>
  </link>
  <joint name="panda_joint7" type="revolute">
    <safety_controller k_position="100.0" k_velocity="40.0" soft_lower_limit="-30" soft_upper_limit="30"/>
    <origin rpy="0 0 0" xyz="0 0 0"/>
    <parent link="panda_link6"/>
    <child link="panda_link7"/>
    <axis xyz="0 0 1"/>
    <limit effort="87" lower="-60" upper="60" velocity="30"/>
    <dynamics damping="0.0" friction="0.0"/>
  </joint>


  <!-- hand starts here -->
  <link name="panda_link8">
    <inertial>
      <mass value="0.01"/>
      <origin rpy="0 0 0" xyz="0 0 0"/>
      <inertia ixx="0.001" ixy="0" ixz="0" iyy="0.001" iyz="0" izz="0.001"/>
    </inertial>
  </link>
  <joint name="panda_joint8" type="fixed">
    <origin rpy="0 0 0" xyz="0 0 0.107"/>
    <parent link="panda_link7"/>
    <child link="panda_link8"/>
    <axis xyz="0 0 0"/>
  </joint>
  <joint name="panda_hand_joint" type="fixed">
    <parent link="panda_link8"/>
    <child link="panda_hand"/>
    <origin rpy="0 0 -0.785398163397" xyz="0 0 0"/>
  </joint>
  <link name="panda_hand">
    <inertial>
      <mass value="0.73"/>
      <origin rpy="0 0 0" xyz="0 0.0015244 0.0275912"/>
      <inertia ixx="0.00278560230025" ixy="0.0" ixz="0.0" iyy="0.000400033405336" iyz="0.0" izz="0.00256378041832"/>
    </inertial>
    <visual>
      <origin rpy="0 0 0" xyz="0 0 0"/>
      <geometry>
        <mesh filename="mppi_panda/resources/panda/meshes/visual/hand.dae"/>
      </geometry>
      <material name="">
        <color rgba="1 1 1 1"/>
      </material>
    </visual>
    <collision>
      <!--origin rpy="0 0 0" xyz="0 0 0"/-->
      <origin rpy="0 0 0" xyz="0 0 0.0333"/>
      <geometry>
        <box size="0.035 0.19 0.065"/>
      </geometry>
      <material name="">
        <contact name="steel"/>
        <!-- for raisim -->
      </material>
    </collision>
  </link>
  <gazebo reference="panda_hand"/>
  <gazebo reference="panda_leftfinger"/>
  <gazebo reference="panda_rightfinger"/>
  <transmission name="panda_finger_joint1_trans">
    <type>transmission_interface/SimpleTransmission</type>
    <joint name="panda_finger_joint1">
      <hardwareInterface>hardware_interface/PositionJointInterface</hardwareInterface>
    </joint>
    <actuator name="panda_finger_joint1_motor">
      <mechanicalReduction>1</mechanicalReduction>
    </actuator>
  </transmission>
  <transmission name="panda_finger_joint2_trans">
    <type>transmission_interface/SimpleTransmission</type>
    <joint name="panda_finger_joint2">
      <hardwareInterface>hardware_interface/PositionJointInterface</hardwareInterface>
    </joint>
    <actuator name="panda_finger_joint2_motor">
      <mechanicalReduction>1</mechanicalReduction>
    </actuator>
  </transmission>
  <link name="panda_leftfinger">
    <inertial>
      <mass value="0.01"/>
      <origin rpy="0 0 0" xyz="0 0.0145644 0.0227941"/>
      <inertia ixx="0.001" ixy="0.0" ixz="0.0" iyy="0.01" iyz="0.0" izz="0.001"/>
    </inertial>
    <visual>
      <origin rpy="0.0 0 3.14159265359" xyz="0 0.022 0.039"/>
      <geometry>
        <box size="0.021 0.009 0.070"/>
      </geometry>
      <material name="">
        <color rgba="1 1 1 1"/>
      </material>
    </visual>
    <visual>
      <origin rpy="0.0 0 3.14159265359" xyz="0 0.014 0.0665"/>
      <geometry>
        <box size="0.021 0.025 0.015"/>
      </geometry>
    </visual>
    <collision>
      <origin rpy="0.0 0 3.14159265359" xyz="0 0.022 0.039"/>
      <geometry>
        <box size="0.021 0.009 0.070"/>
      </geometry>
      <material name="">
        <contact name="steel"/>
        <!-- for raisim -->
      </material>
    </collision>
    <collision>
      <origin rpy="0.0 0 3.14159265359" xyz="0 0.014 0.0665"/>
      <geometry>
        <box size="0.021 0.025 0.015"/>
      </geometry>
      <material name="">
        <contact name="steel"/>
        <!-- for raisim -->
      </material>
    </collision>
  </link>
  <link name="panda_rightfinger">
    <inertial>
      <mass value="0.01"/>
      <origin rpy="0 0 0" xyz="0 0.0145644 0.0227941"/>
      <inertia ixx="0.001" ixy="0.0" ixz="0.0" iyy="0.01" iyz="0.0" izz="0.001"/>
    </inertial>
  </link>
  <joint name="panda_finger_joint1" type="prismatic">
    <parent link="panda_hand"/>
    <child link="panda_leftfinger"/>
    <origin rpy="0 0 0" xyz="0 0 0.0584"/>
    <!-- 0.0584 -->
    <axis xyz="0 1 0"/>
    <limit effort="20" lower="-0.001" upper="0.04" velocity="0.3"/>
  </joint>
  <joint name="panda_finger_joint2" type="prismatic">
    <parent link="panda_hand"/>
    <child link="panda_rightfinger"/>
    <origin rpy="0 0 0" xyz="0 0 0.0584"/>
    <!-- 0.064 -->
    <axis xyz="0 -1 0"/>
    <limit effort="20" lower="-0.001" upper="0.04" velocity="0.3"/>
  </joint>
  <link name="panda_grasp"/>
  <joint name="panda_grasp_joint" type="fixed">
    <parent link="panda_hand"/>
    <child link="panda_grasp"/>
    <axis xyz="0 1 0"/>
    <origin rpy="0 0 0" xyz="0 0 0.095"/>
    <!-- 0.106-->
  </joint>
  <link name="panda_grasp_finger"/>
  <joint name="panda_grasp__finger_joint" type="fixed">
    <parent link="panda_hand"/>
    <child link="panda_grasp_finger"/>
    <axis xyz="0 1 0"/>
    <origin rpy="0 0 0" xyz="0 0.025 0.125"/>
    <!-- 0.106-->
  </joint>
  <link name="panda_grasp_finger_edge"/>
  <joint name="panda_grasp__finger_edge_joint" type="fixed">
    <parent link="panda_hand"/>
    <child link="panda_grasp_finger_edge"/>
    <axis xyz="0 1 0"/>
    <origin rpy="0 0 0" xyz="0 0.04 0.15"/>
    <!-- 0.106-->
  </joint>
</robot>

